Workbook

Sheet 00 Kit Guide
A1: Databricks Medallion Layer Starter Kit / Workshop Kit
A2: Editable source tab. Use this workbook to move from early source inventory and workshop planning through Bronze-to-Silver design, governance decisions, Gold product definition, and implementation follow-through. Domain-specific example workbooks may exist separately and can be used as references, but they are not part of the core enterprise starter kit.
A4: Quick metric | B4: Current value | D4: Tab | E4: Purpose | F4: Required? | G4: Primary stage | H4: Primary users | J4: Important note
A5: Total sources listed | B5: =COUNTA('02 Source Inventory'!A6:A2000) -> 2 | D5: 02 Source Inventory | E5: Log sources, ownership, grain, scope, and complexity | F5: Required | G5: Workshop prep | H5: Sponsor; stewards; architects | J5: This is the enterprise core kit.
A6: In-scope sources | B6: =COUNTIF('02 Source Inventory'!U6:U2000,"Yes") -> 2 | D6: 03 Bronze Intake | E6: Capture Bronze landing, lineage, and early planning details | F6: Required | G6: Workshop prep | H6: Project lead; engineers; vendor manager | J6: Use separate example workbooks for domain-specific reference patterns.
A7: Open decisions | B7: =COUNTIF('09 Decisions'!O6:O2000,"Open") -> 1 | D7: 01 Workshop Plan | E7: Plan sessions, participants, agenda focus, and outputs | F7: Optional | G7: Facilitation | H7: Facilitator; PM; sponsors
A8: Open risks / issues / dependencies | B8: =COUNTIF('10 RAID Log'!J6:J2000,"Open") -> 2 | D8: 04 Silver Field Treatment | E8: Work line-by-line through Bronze-to-Silver field treatment decisions | F8: Required | G8: Design | H8: Business SMEs; stewards; engineers
A9: Gold products defined | B9: =COUNTA('06 Gold Product'!A6:A2000) -> 1 | D9: 05 Data Quality Rules | E9: Document validation and acceptability rules | F9: Required | G9: Design | H9: Stewards; analysts; QA
D10: 06 Gold Product | E10: Define Gold purpose, grain, refresh, and ownership | F10: Required | G10: Follow-through | H10: Business owners; BI leads
D11: 07 Access & Sharing | E11: Track consumers, restrictions, and approvals | F11: Required | G11: Governance | H11: Owner; steward; security
A13: Workbook tab groups
A14: Editable source tabs | D14: Generated role-based tabs
A15: 00–10 | B15: Use these tabs to capture and maintain the source-of-truth content for the process. | D15: 90–92 | E15: Use these tabs as read-only audience outputs for sponsors, stewards, and implementers.
A17: Admin tab
A18: 11 Lists | B18: Maintain dropdown values and workbook controls here. General participants usually should not edit this tab.

Sheet 01 Workshop Plan
A1: 01 Workshop Plan
A2: Editable source tab. Use this tab to organize workshop sessions, clarify required participants, and make sure each session has a narrow objective and expected outputs.
A3: Session basics | E3: What the session must produce | I3: Follow-through
A4: Session ID | B4: Workshop Date | C4: Domain / Source | D4: Session Objective | E4: Participants | F4: Pre-Reads / Inputs | G4: Key Decisions Needed | H4: Expected Outputs | I4: Facilitator | J4: Status | K4: Notes
A5: Unique identifier for the workshop or working session. | B5: Scheduled date. | C5: Primary domain, source, or subject area for the session. | D5: What the group must accomplish. | E5: Core attendees and required roles. | F5: Artifacts participants should review beforehand. | G5: Decisions that must be made in the session. | H5: Artifacts or updates expected from the session. | I5: Primary session lead. | J5: Planning status. | K5: Additional logistics or follow-up notes.
A6: WS-001 | B6: 2026-05-06 | C6: Enterprise Licensing System | D6: Inventory source domains and establish treatment approach for high-priority entities | E6: Licensing owner; steward; BIT architect; security; vendor liaison | F6: Source inventory; Bronze intake; example template | G6: Authoritative source, target grain, scope of first transformation cycle | H6: Updated inventory, initial field treatment rows, open decision list | I6: BIT | J6: Planned | K6: Do not expect to review all data in one afternoon; focus on patterns and highest-value areas.

Sheet 02 Source Inventory
A1: 02 Source Inventory
A2: Editable source tab. Use this tab before field-level work begins. Capture enough information to prioritize sources, identify owners, and decide which sources are ready for line-by-line review.
A3: Ownership & context | G3: Source profile | P3: Use, risk & scope
A4: Source ID | B4: Source Name | C4: Program / Business Area | D4: Source Owner | E4: Business Steward | F4: Technical Contact | G4: Source Type | H4: System of Record? | I4: Primary Purpose | J4: Record Grain | K4: Approximate Record Volume | L4: Approximate Field Count | M4: Refresh Frequency | N4: Delivery Method | O4: Key Identifiers | P4: Sensitive / Regulated Data? | Q4: Known Downstream Consumers | R4: Vendor Consumer? | S4: Priority | T4: Complexity | U4: In Scope for Current Effort? | V4: Notes
A5: Unique short identifier for the source system or feed. | B5: Plain-language name of the source system, file, or feed. | C5: Agency program, bureau, or functional domain. | D5: Business owner accountable for the source. | E5: Primary steward or SME for definitions and quality. | F5: Technical lead or system contact. | G5: Application, database, API, file feed, SaaS, etc. | H5: Whether this source is authoritative for some domain or entity. | I5: Operational, reporting, exchange, analytics, regulatory, etc. | J5: What one row or record represents. | K5: Estimated number of records or files. | L5: Estimated count of candidate fields or variables. | M5: How often data arrives or changes. | N5: Batch file, API, stream, manual extract, replication, etc. | O5: Primary identifiers available in the source. | P5: Whether regulated or highly sensitive data is present. | Q5: Who uses or expects to use the data. | R5: Whether a vendor is an expected consumer. | S5: Relative priority for the current effort. | T5: Relative complexity for transformation/governance work. | U5: Whether the source is in scope now. | V5: Important context, caveats, or assumptions.
A6: SRC-001 | B6: Enterprise Licensing System | C6: Professional Licensing | D6: Licensing Director | E6: Licensing Program Steward | F6: BIT integration lead | G6: Application | H6: Yes | I6: Operational licensing and renewals | J6: One row per license record | K6: 1.2M records | L6: 900 | M6: Daily | N6: Database extract | O6: License ID; Person ID | P6: Yes | Q6: Internal analytics; portal vendor | R6: Yes | S6: High | T6: High | U6: Yes | V6: Large source with many status and history fields; likely requires phased review.
A7: SRC-002 | B7: Grant Payments File | C7: Department of Finance | D7: Chief Financial Officer | E7: Finance Steward | F7: ERP data engineer | G7: File feed | H7: No | I7: Disbursement and reconciliation | J7: One row per payment transaction | K7: 250K records | L7: 120 | M7: Weekly | N7: Secure file transfer | O7: Payment ID; Vendor ID | P7: Yes | Q7: Finance analysts; auditors | R7: No | S7: Medium | T7: Medium | U7: Yes | V7: Good candidate for early pilot because grain is clear.

Sheet 03 Bronze Intake
A1: 03 Bronze Intake
A2: Editable source tab. Capture early scoping information. This tab is intentionally lighter than the field treatment workbook and supports progressive elaboration rather than full rule definition up front.
A3: Bronze Intake | O3: Readiness & Controls
A4: Intake ID | B4: Source Name | C4: Source Dataset/Object Name | D4: Bronze Dataset / Object Name | E4: Program / Business Area | F4: Business Objective | G4: Source Type | H4: Proposed Bronze Landing Method | I4: Landing Frequency | J4: Source Format | K4: Schema Stability | L4: Primary Identifiers Present | M4: Record Grain | N4: Raw Lineage / Load Metadata Captured? | O4: Retention Expectation | P4: Sensitive Data Present? | Q4: Bronze Access Constraints | R4: Data Quality Concerns Observed at Intake | S4: In Scope This Cycle? | T4: Owner | U4: Status | V4: Notes
A5: Unique identifier for the Bronze intake record. | B5: Plain-language name of the source system, feed, or file. | C5: The original file, table, API object, extract, or source-side dataset name as it exists in the upstream source system. | D5: The name of the landed object in the Bronze layer after it is brought into the platform, using the Bronze naming convention if one exists. | E5: Agency program, bureau, or functional domain associated with the source. | F5: Why this source is being onboarded or reviewed. | G5: Type of source, such as application, database, API, flat file, SaaS export, or event stream. | H5: Proposed method for how the source will land in Bronze, including batch file, replication, API pull, streaming, or manual delivery. | I5: Expected cadence of Bronze ingestion, such as daily, weekly, monthly, near real-time, or on demand. | J5: Format of the source payload, such as CSV, JSON, XML, Parquet, relational table, Excel, or API response. | K5: How stable the incoming structure is over time and how often schema changes are expected. | L5: Key identifiers available in the raw source at intake. | M5: What one raw source row or record represents in Bronze. | N5: Whether Bronze captures load timestamp, source filename, extract date, source system metadata, or other lineage details. | O5: Expected retention period or archive expectation for Bronze data. | P5: Whether the raw source contains confidential, restricted, or regulated information. | Q5: Constraints on who can access the Bronze landing zone or raw dataset. | R5: Known issues visible before Silver design begins, such as null-heavy fields, malformed values, or unstable extracts. | S5: Whether this Bronze dataset is in scope for the current design or delivery cycle. | T5: Accountable business or delivery owner for intake and progression. | U5: Current intake status. | V5: Additional intake notes, assumptions, or caveats.
A6: INT-001 | B6: =IF(Table5[[#This Row],[Source Name]]="","-",Table5[[#This Row],[Source Name]]) -> Enterprise Licensing System | C6: license_master | D6: brz_licensing_license_master | E6: Professional Licensing | F6: Standardize raw licensing source for enterprise reuse | G6: Application | H6: Daily extract landed unchanged with load timestamp | I6: Daily | J6: CSV | K6: Moderate | L6: license_id; person_id | M6: One row per license record | N6: Yes | O6: 7 years | P6: Yes | Q6: Restricted to implementation team and approved stewards | R6: Status field is inconsistently populated in some extracts | S6: Yes | T6: Licensing Director | U6: Ready for Silver Design | V6: Source contains active and historical records
A7: INT-002 | B7: =IF(Table5[[#This Row],[Source Name]]="","-",Table5[[#This Row],[Source Name]]) -> Grant Payments File | C7: payments_weekly.csv | D7: brz_finance_payments_weekly | E7: Finance | F7: Prepare grant payment data for enterprise reporting and external extracts | G7: File Feed | H7: Weekly file landed unchanged with source filename and load date | I7: Weekly | J7: CSV | K7: Stable | L7: payment_id; grant_id; recipient_id | M7: One row per payment transaction | N7: Yes | O7: 7 years | P7: Yes | Q7: Restricted to finance delivery and approved stewards | R7: Adjustment rows may use zero-dollar amounts; funding codes occasionally drift | S7: Yes | T7: Chief Financial Officer | U7: In Review | V7: History tracking expected only in downstream Silver if needed for audit trends
B8: =IF(Table5[[#This Row],[Source Name]]="","-",Table5[[#This Row],[Source Name]]) -> -
B9: =IF(Table5[[#This Row],[Source Name]]="","-",Table5[[#This Row],[Source Name]]) -> -
B10: =IF(Table5[[#This Row],[Source Name]]="","-",Table5[[#This Row],[Source Name]]) -> -
B11: =IF(Table5[[#This Row],[Source Name]]="","-",Table5[[#This Row],[Source Name]]) -> -
B12: =IF(Table5[[#This Row],[Source Name]]="","-",Table5[[#This Row],[Source Name]]) -> -
B13: =IF(Table5[[#This Row],[Source Name]]="","-",Table5[[#This Row],[Source Name]]) -> -
B14: =IF(Table5[[#This Row],[Source Name]]="","-",Table5[[#This Row],[Source Name]]) -> -
B15: =IF(Table5[[#This Row],[Source Name]]="","-",Table5[[#This Row],[Source Name]]) -> -
B16: =IF(Table5[[#This Row],[Source Name]]="","-",Table5[[#This Row],[Source Name]]) -> -
B17: =IF(Table5[[#This Row],[Source Name]]="","-",Table5[[#This Row],[Source Name]]) -> -
B18: =IF(Table5[[#This Row],[Source Name]]="","-",Table5[[#This Row],[Source Name]]) -> -
B19: =IF(Table5[[#This Row],[Source Name]]="","-",Table5[[#This Row],[Source Name]]) -> -
... B100: =IF(Table5[[#This Row],[Source Name]]="","-",Table5[[#This Row],[Source Name]]) -> -

Sheet 04A Silver Dataset Design
A1: 04A Silver Dataset Design
A2: Editable source tab. Define the general Silver-layer dataset structure, target grain, source inputs, and major design patterns before field-level treatment begins.
A3: Bronze Intake
A4: Silver Design ID | B4: Source Name | C4: Bronze Dataset / Object Name | D4: Target Silver Dataset | E4: Target Silver Table / View Name | F4: Business Entity | G4: Silver Purpose | H4: Target Grain | I4: Source Inputs Included | J4: Split Needed? | K4: Merge / Join Needed? | L4: Major Transformation Patterns | M4: Major Reference Data Needed | N4: Sensitive Data Controls | O4: Primary Consumers | P4: Vendor / External Use Expected? | Q4: In Scope This Cycle? | R4: Owner | S4: Steward | T4: Status | U4: Notes
A5: Unique identifier for the Silver dataset design record. | B5: Source system or feed contributing to the Silver dataset. | C5: The name of the landed object in the Bronze layer after it is brought into the platform, using the Bronze naming convention if one exists. | D5: Plain-language name of the Silver dataset or subject area. | E5: Planned physical or logical Silver object name. | F5: Core business concept represented for this dataset, such as person, license, case, payment, asset, encounter, or grant. | G5: Why this Silver dataset exists and what reusable need it supports. | H5: What one row in the Silver dataset will represent. | I5: Main Bronze inputs or related datasets feeding this Silver object. | J5: Whether one Bronze dataset will be split into multiple Silver targets. | K5: Whether multiple inputs must be combined to produce the Silver target. | L5: High-level transformation approach, such as standardize codes, normalize status, derive dates, flatten nested structures, or conform identifiers. | M5: High-level reference tables, code sets, or lookup structures needed for the Silver design. | N5: High-level masking, restriction, de-identification, or segregation approach expected in Silver. | O5: Main internal or downstream users of the Silver dataset. | P5: Whether the Silver dataset or its downstream outputs will support vendor or external use. | Q5: Whether this Silver design item is included in the current phase. | R5: Accountable owner for the Silver design. | S5: Steward or business lead responsible for definitions and review. | T5: Current design status. | U5: Additional design notes, assumptions, or unresolved questions.
A6: SD-001 | B6: =IF(Table5[[#This Row],[Source Name]]="","-",Table5[[#This Row],[Source Name]]) -> Enterprise Licensing System | C6: =IF(Table6[[#This Row],[Bronze Dataset / Object Name]]="","-",Table6[[#This Row],[Bronze Dataset / Object Name]]) -> brz_licensing_license_master | D6: Licensing License Silver | E6: slv_licensing_license | F6: License | G6: Create a reusable enterprise license table with standardized status, dates, and identifiers | H6: One row per current license | I6: license_master; licensing status reference | J6: No | K6: No | L6: Standardize status codes, normalize dates, carry forward enterprise identifiers | M6: Licensing status reference list | N6: Restrict internal notes; exclude fields not needed for Silver reuse | O6: Operations reporting; vendor extract process; BI | P6: Yes | Q6: Yes | R6: Licensing Director | S6: Licensing Steward | T6: In Progress | U6: Historical disciplinary detail may move to a separate Silver object later
A7: SD-002 | B7: =IF(Table5[[#This Row],[Source Name]]="","-",Table5[[#This Row],[Source Name]]) -> Grant Payments File | C7: =IF(Table6[[#This Row],[Bronze Dataset / Object Name]]="","-",Table6[[#This Row],[Bronze Dataset / Object Name]]) -> brz_finance_payments_weekly | D7: Grant Payment Silver | E7: slv_finance_grant_payment | F7: Grant Payment | G7: Create a reusable payment-level Silver dataset for finance reporting and controlled external extracts | H7: One row per payment transaction | I7: payments_weekly.csv; funding code reference | J7: No | K7: No | L7: Validate amounts, standardize funding codes, normalize dates and recipient identifiers | M7: Funding code reference list | N7: Restrict internal comments and bank-routing-related fields | O7: Finance reporting; external extract process; BI | P7: Yes | Q7: Yes | R7: Chief Financial Officer | S7: Finance Steward | T7: Draft | U7: Potential future join to grant master dataset for richer conformed reporting

Sheet 04B Silver Field Treatment
A1: 04 Silver Field Treatment
A2: Editable source tab. Use this as a hybrid workshop + follow-through tab. The left side is business-first for live sessions. This tab specifically documents how fields move from Bronze into the Silver layer. Advanced technical details are pushed to the right so teams can progressively elaborate without losing workshop momentum.
A3: Source context | J3: Silver design | S3: Governance | X3: Advanced detail
A4: Source Name | B4: Bronze Dataset / Object Name | C4: Target Silver Dataset | D4: Source Field Name | E4: Source Field Label | F4: Source Definition | G4: Sample Values | H4: Required in Source? | I4: Null / Blank Behavior in Source | J4: Target Silver Table | K4: Target Silver Field Name | L4: Target Silver Definition | M4: Keep in Silver? | N4: Treatment Category | O4: Transformation Rule Summary | P4: Decision Status | Q4: Owner / Reviewer | R4: Open Issue / Note | S4: Sensitive Classification | T4: Mask / Restrict Rule | U4: Consumer-Specific Only? | V4: Data Quality Rules Applied | W4: Source of Truth / Authority Note | X4: Source Data Type | Y4: Source Format / Length | Z4: Target Data Type | AA4: Detailed Transformation Logic | AB4: Reference Mapping Needed? | AC4: Reference Table / Value Set | AD4: Derived Field?
A5: Source system or feed contributing to the Silver dataset. | B5: The name of the landed object in the Bronze layer after it is brought into the platform, using the Bronze naming convention if one exists. | C5: Plain-language name of the Silver dataset or subject area. | D5: Original field or variable name. | E5: Plain-language label if different from field name. | F5: Known source-side meaning or definition. | G5: Representative examples from the source. | H5: Whether the source expects this value. | I5: How missing or blank values appear in the source. | J5: Planned Silver table or object. | K5: Field name in Silver. | L5: Plain-language business definition in Silver. | M5: Whether this field belongs in Silver. | N5: High-level treatment decision for the field. | O5: Short description of the treatment. | P5: Current field-design status. | Q5: Who must confirm the rule. | R5: Unresolved question or important note. | S5: Data sensitivity level. | T5: Any masking or restriction expectation. | U5: Whether a transformation belongs downstream instead of Silver. | V5: Applicable quality rule IDs or shorthand. | W5: Authority or survivorship note if relevant. | X5: Raw source data type. | Y5: Source format, pattern, or length. | Z5: Data type expected in Silver. | AA5: Implementation-oriented logic or rule details. | AB5: Whether a controlled list or lookup is required. | AC5: Name of the reference or code set. | AD5: Whether the target value is derived.
A6: Enterprise Licensing System | B6: =IF(Table6[[#This Row],[Bronze Dataset / Object Name]]="","-",Table6[[#This Row],[Bronze Dataset / Object Name]]) -> brz_licensing_license_master | C6: Licensing License Silver | D6: license_status | E6: License Status | F6: Current status recorded by licensing program | G6: ACTIVE; INACTIVE; LAPSED | H6: Yes | I6: Blank when source process fails to set status | J6: slv_licensing_license | K6: license_status_code | L6: Normalized current license status | M6: Yes | N6: Map | O6: Map source statuses to enterprise licensing status list | P6: In Progress | Q6: Licensing steward | R6: Need decision on how to handle pending-renewal versus active. | S6: Internal | T6: None | U6: No | V6: DQ-004 | W6: Licensing source authoritative unless superseded by adjudication feed | X6: string | Y6: varchar(20) | Z6: string | AA6: Use reference map; preserve raw status in Bronze; route unknowns to review queue | AB6: Yes | AC6: LIC_STATUS_MAP | AD6: No
A7: Grant Payments File | B7: =IF(Table6[[#This Row],[Bronze Dataset / Object Name]]="","-",Table6[[#This Row],[Bronze Dataset / Object Name]]) -> brz_finance_payments_weekly | C7: Grant Payment Silver | D7: amount | E7: Payment Amount | F7: Dollar amount of payment transaction | G7: 1250.00 | H7: Yes | I7: Null not expected | J7: slv_finance_grant_payment | K7: payment_amount | L7: Payment amount in USD | M7: Yes | N7: Validate | O7: Preserve numeric value and validate non-negative unless reversal indicator present | P7: Draft | Q7: Finance steward | R7: Need rule for zero-dollar adjustment rows. | S7: Confidential | T7: None | U7: No | V7: DQ-007 | W7: Finance file authoritative for disbursement amount | X7: decimal | Y7: 12,2 | Z7: decimal(12,2) | AA7: Cast to decimal; if negative, require reversal reason flag | AB7: No | AD7: No

Sheet 05 Data Quality Rules
A1: 05 Data Quality Rules
A2: Editable source tab. Use this tab to document what makes data acceptable. This tab is rule-centric, not field-centric. Link rule IDs back to the field treatment workbook where helpful.
A3: Rule definition | I3: Severity & exception handling | O3: Ownership & implementation
A4: Rule ID | B4: Rule Name | C4: Source / Dataset | D4: Target Layer | E4: Business Entity | F4: Applies to Field(s) | G4: Rule Type | H4: Rule Description | I4: Severity | J4: Threshold / Tolerance | K4: Expected Behavior if Failed | L4: Exception Handling | M4: Business Rationale | N4: Owner | O4: Implementation Status | P4: Monitoring Needed? | Q4: Notes
A5: Unique identifier for the data quality rule. | B5: Short name for the rule. | C5: Source or target dataset the rule applies to. | D5: Bronze, Silver, or Gold. | E5: Entity or domain the rule applies to. | F5: Field or fields covered by the rule. | G5: Type of validation or acceptability rule. | H5: Business-readable description of the rule. | I5: Criticality of a failure. | J5: Allowed tolerance before escalation. | K5: What happens when the rule fails. | L5: How exceptions are reviewed or approved. | M5: Why the rule matters. | N5: Who owns the rule. | O5: Current implementation status. | P5: Whether ongoing monitoring is expected. | Q5: Additional implementation or stewardship notes.
A6: DQ-004 | B6: Normalize license status values | C6: Enterprise Licensing System | D6: Silver | E6: License | F6: license_status_code | G6: Allowed Value | H6: Target status must be one of the approved enterprise licensing status values. | I6: High | J6: 0 unapproved values in published Silver dataset | K6: Reject or quarantine rows with unrecognized mapped value until reviewed. | L6: Steward may approve temporary mapping additions through decision log. | M6: Prevents inconsistent status interpretation across consumers. | N6: Licensing steward | O6: Draft | P6: Yes | Q6: Reference map should be versioned and reviewed.
A7: DQ-007 | B7: Payment amount sign rule | C7: Grant Payments File | D7: Silver | E7: Grant Payment | F7: payment_amount; reversal_flag | G7: Cross-Field Consistency | H7: Negative payment amounts are only allowed when reversal_flag = Yes. | I7: High | J7: 0 invalid negative amounts | K7: Block publish to Silver review set until resolved. | L7: Finance steward and engineering lead review exceptions. | M7: Protects downstream financial reporting accuracy. | N7: Finance steward | O7: Not Started | P7: Yes | Q7: Need agreement on zero-dollar adjustment handling.

Sheet 06 Gold Product
A1: 06 Gold Product
A2: Editable source tab. Use this tab to define analytics-ready or product-oriented outputs. Gold should have a clear purpose, grain, refresh expectation, ownership model, and access expectation.
A3: Product framing | G3: Service expectations | K3: Ownership & governance | P3: Readiness & notes
A4: Product ID | B4: Gold Product Name | C4: Business Purpose | D4: Primary Consumers | E4: Source Silver Dataset(s) | F4: Record Grain | G4: Key Measures / Dimensions | H4: Refresh Frequency | I4: Latency / SLA Expectation | J4: Access Method | K4: Data Owner | L4: Data Steward | M4: Data Custodian | N4: Sensitive Classification | O4: Data Contract Needed? | P4: Definition of Done | Q4: Status | R4: Notes
A5: Unique identifier for the Gold data product. | B5: Plain-language name of the Gold dataset or product. | C5: Why the product exists and what decision or service it supports. | D5: Who will use the product. | E5: Silver datasets that feed the product. | F5: What one row in the product represents. | G5: Main measures, dimensions, or subject areas included. | H5: Expected refresh cadence. | I5: Timing expectation for delivery or freshness. | J5: How consumers will receive or use the product. | K5: Business owner for the product. | L5: Steward for definitions, quality, and changes. | M5: Technical custodian or platform lead. | N5: Sensitivity level of the product. | O5: Whether a formal contract should be defined. | P5: What must be true for the product to be considered ready. | Q5: Current lifecycle status. | R5: Additional implementation or governance notes.
A6: GLD-001 | B6: Licensing Operations Summary | C6: Provide a reusable monthly and weekly view of license counts and status trends for operations and portal planning. | D6: Licensing leadership; portal vendor; executive dashboard | E6: slv_licensing_license | F6: One row per license per reporting period | G6: Counts by status, profession, geography, renewal cycle | H6: Daily | I6: Available by 7 a.m. each business day | J6: View | K6: Licensing Director | L6: Licensing Program Steward | M6: BIT data platform lead | N6: Internal | O6: Yes | P6: Business-approved definitions, refreshed on schedule, access approved, and key DQ rules monitored. | Q6: Draft | R6: Vendor extract should be downstream from this product, not the design center for Silver.

Sheet 07 Access & Sharing
A1: 07 Access & Sharing
A2: Editable source tab. Make sharing expectations visible early. Use this tab to document who needs access, to which layer, for what purpose, and with what restrictions or approvals.
A3: Consumer request | F3: Scope & controls | K3: Decision & review
A4: Dataset / Product | B4: Layer | C4: Consumer Group | D4: Business Purpose | E4: Access Method | F4: Minimum Necessary Scope | G4: Row / Column Restrictions | H4: De-identification Needed? | I4: Approval Required From | J4: DUA / DSA / Contract Needed? | K4: Access Decision | L4: Expiration / Review Date | M4: Notes
A5: Dataset or product for which access is being considered. | B5: Bronze, Silver, or Gold. | C5: Team, role, vendor, or application requesting access. | D5: Why access is needed. | E5: Direct table, view, extract, API, BI tool, etc. | F5: Subset or scope actually needed. | G5: Any row-level, column-level, or field-level restrictions. | H5: Whether masking or de-identification is required. | I5: Who must approve the access. | J5: Whether a sharing or access agreement is required. | K5: Current access decision status. | L5: When access should be re-reviewed. | M5: Additional sharing or restriction notes.
A6: slv_licensing_license | B6: Silver | C6: Portal Vendor | D6: Support portal display of active licenses only | E6: Curated extract | F6: Active licenses and approved public fields | G6: Exclude sensitive internal notes and historical disciplinary comments | H6: Yes | I6: Data owner; security; privacy | J6: Yes | K6: Requested | L6: 2026-12-31 | M6: Prefer curated downstream extract instead of broad Silver access.

Sheet 08 Roles
A1: 08 Roles
A2: Editable source tab. Clarify owner, steward, custodian, SME, and reviewer responsibilities. This tab helps keep workshops from becoming discussions without decision rights.
A3: Role assignment | E3: Responsibility & authority | H3: Tracking
A4: Domain / Source | B4: Dataset / Product | C4: Role Type | D4: Person / Group | E4: Responsibilities | F4: Decision Rights | G4: Escalation Path | H4: Status | I4: Notes
A5: Domain, source, or dataset context. | B5: Specific dataset or product. | C5: Owner, steward, custodian, SME, etc. | D5: Named person, office, or team. | E5: Core responsibilities for the role. | F5: What the role can approve or decide. | G5: Who or what forum resolves disputes. | H5: Current assignment status. | I5: Additional accountability notes.
A6: Licensing | B6: slv_licensing_license | C6: Data Owner | D6: Licensing Director | E6: Approves business purpose, access, and major structural decisions. | F6: Approves Gold product purpose and sensitive-access decisions. | G6: Escalate unresolved cross-domain questions to enterprise governance forum. | H6: Confirmed | I6: Could delegate day-to-day review to program manager while retaining decision authority.
A7: Licensing | B7: slv_licensing_license | C7: Data Steward | D7: Licensing Program Steward | E7: Defines business meaning, mappings, and quality expectations. | F7: Approves field definitions and code mappings. | G7: Escalate unresolved policy questions to data owner and governance lead. | H7: Confirmed | I7: Primary reviewer for status, profession, and renewal fields.

Sheet 09 Decisions
A1: 09 Decisions
A2: Editable source tab. Use this tab for cross-cutting decisions and rationale that should not be buried inside a single field row. Reference decision IDs back into other tabs where helpful.
A3: Decision framing | F3: Reasoning & impact | K3: Follow-through
A4: Decision ID | B4: Date Raised | C4: Topic | D4: Scope | E4: Decision Statement | F4: Options Considered | G4: Rationale | H4: Decision Maker | I4: Effective Date | J4: Affected Artifact | K4: Affected Source(s) | L4: Follow-Up Action | M4: Action Owner | N4: Due Date | O4: Status | P4: Notes
A5: Unique identifier for the decision. | B5: Date the decision was first raised. | C5: Short topic name. | D5: Source, domain, or dataset in scope. | E5: What was decided or what requires approval. | F5: Main options considered. | G5: Why the chosen path was selected. | H5: Approver or decision-making body. | I5: When the decision takes effect. | J5: Workbook tab, standard, mapping, contract, or implementation artifact affected. | K5: Source systems or datasets affected. | L5: What must happen next because of the decision. | M5: Person responsible for follow-up. | N5: Target date for follow-up. | O5: Open, approved, deferred, etc. | P5: Additional context or exceptions.
A6: DEC-001 | B6: 2026-05-06 | C6: Vendor access design | D6: Enterprise Licensing System | E6: Silver will be designed for enterprise reuse first; vendor-specific shaping will occur through downstream curated extracts or Gold products. | F6: Direct Silver access; curated extract; vendor-specific Silver branch | G6: Protects long-term maintainability and avoids shaping Silver around a single consumer. | H6: Licensing Director | I6: 2026-05-06 | J6: Access & Sharing; Gold Data Product; Field Treatment | K6: Enterprise Licensing System | L6: Define vendor extract scope and approval path. | M6: Data strategy lead | N6: 2026-05-20 | O6: Open | P6: Confirm whether any public fields can be served directly from Gold view.

Sheet 10 RAID Log
A1: 10 RAID Log
A2: Editable source tab. Track risks, issues, dependencies, and follow-up actions separately from decisions. This tab supports workshop management and implementation follow-through.
A3: Item framing | E3: Impact & response | I3: Ownership & tracking
A4: RAID ID | B4: Type | C4: Date Raised | D4: Source / Domain | E4: Description | F4: Impact | G4: Likelihood | H4: Mitigation / Next Step | I4: Owner | J4: Status | K4: Due Date | L4: Notes
A5: Unique identifier for the log entry. | B5: Risk, issue, dependency, or action. | C5: Date the item was logged. | D5: Affected source, dataset, or domain. | E5: Plain-language description of the item. | F5: Why it matters. | G5: High, medium, low, if applicable. | H5: Planned response or action. | I5: Person accountable for follow-up. | J5: Current status. | K5: Target resolution or review date. | L5: Additional detail.
A6: RAID-001 | B6: Risk | C6: 2026-05-06 | D6: Enterprise Licensing System | E6: One source contains roughly 900 variables, which could overwhelm the first workshop if the team tries to define every field in one session. | F6: Could stall momentum and produce low-quality decisions. | G6: High | H6: Prioritize highest-value entities and establish repeatable treatment patterns before broad line-by-line review. | I6: Facilitator | J6: Open | K6: 2026-05-13 | L6: Use workshop plan to sequence follow-on sessions.
A7: RAID-002 | B7: Dependency | C7: 2026-05-06 | D7: Grant Payments File | E7: Chart-of-accounts reference list is not yet confirmed. | F7: Mapping and validation cannot be finalized until reference data is approved. | G7: Medium | H7: Escalate to finance steward and CFO office for confirmation. | I7: Finance steward | J7: Open | K7: 2026-05-15 | L7: Link to decision log if policy choice is required.

Sheet 11 Lists
A1: 11 Lists
A2: Admin tab. Maintain controlled values used by dropdowns and generated views. General participants should not need to edit this tab.
A4: Yes / No | C4: Priority | D4: Landing Frequency | E4: Source Type | F4: Complexity | G4: Status - Bronze | H4: Status | J4: Treatment Category | L4: Sensitive Classification | N4: Rule Type | P4: Layer | R4: Role Type | T4: RAID Type | V4: Access Method | X4: Access Decision
A5: Yes | C5: High | F5: High | G5: Draft | H5: Not Started | J5: Pass-through | L5: Public | N5: Required | P5: Bronze | R5: Data Owner | T5: Risk | V5: Direct table access | X5: Requested
A6: No | C6: Medium | D6: Near real-time | E6: Application | F6: Medium | G6: In Review | H6: In Progress | J6: Standardize | L6: Internal | N6: Format | P6: Silver | R6: Data Steward | T6: Issue | V6: View | X6: Approved
C7: Low | D7: Hourly | E7: Database | F7: Low | G7: Ready for Silver Design | H7: Blocked | J7: Validate | L7: Confidential | N7: Allowed Value | P7: Gold | R7: Data Custodian | T7: Dependency | V7: Curated extract | X7: Approved with Restrictions
D8: Daily | E8: API | G8: Blocked | H8: Open | J8: Map | L8: Restricted | N8: Range | R8: Business SME | T8: Action | V8: Dashboard / BI tool | X8: Denied
D9: Weekly | E9: File Feed | G9: Closed | H9: Draft | J9: Derive | L9: Regulated / Sensitive | N9: Uniqueness | R9: Technical Lead | V9: API | X9: Expired
D10: Monthly | E10: SaaS Export | H10: Ready for Review | J10: Enrich | N10: Referential Integrity | R10: Privacy / Security Reviewer | V10: Secure file transfer
D11: Quarterly | E11: Spreadsheet | H11: Approved | J11: Restrict | N11: Timeliness | R11: Implementation Partner
D12: On demand | E12: Event Stream | H12: Closed | J12: Exclude | N12: Cross-Field Consistency
D13: Other | E13: Other | H13: Deferred | N13: Duplicate Detection
N14: Business Logic
N15: Anomaly / Variance

Sheet 90 Facilitator & Sponsor View
A1: 90 Facilitator & Sponsor View
A2: Generated role-based view — do not edit. Generated view — do not edit. This tab gives sponsors and facilitators a concise summary of scope, progress, open decisions, and open RAID items. Update source tabs and refresh the workbook instead of editing this view directly.
A4: Quick metric | B4: Current value | D4: Scope & progress
A5: Total sources listed | B5: =COUNTA('02 Source Inventory'!B6:B500) -> 2 | D5: Source Name | E5: Program / Area | F5: Priority | G5: Complexity | H5: In Scope? | I5: Bronze Status | J5: Source Owner
A6: In-scope sources | B6: =COUNTIF('02 Source Inventory'!U6:U500,"Yes") -> 2 | D6: =IF('02 Source Inventory'!B6<>"",'02 Source Inventory'!B6,"") -> Enterprise Licensing System | E6: =IF(D6<>"",'02 Source Inventory'!C6,"") -> Professional Licensing | F6: =IF(D6<>"",'02 Source Inventory'!S6,"") -> High | G6: =IF(D6<>"",'02 Source Inventory'!T6,"") -> High | H6: =IF(D6<>"",'02 Source Inventory'!U6,"") -> Yes | I6: =IF(D6<>"",IFERROR(_xludf.XLOOKUP(D6,'03 Bronze Intake'!B$6:B$367,'03 Bronze Intake'!V$6:V$367,""),""),"") | J6: =IF(D6<>"",'02 Source Inventory'!D6,"") -> Licensing Director
A7: Open decisions | B7: =COUNTIF('09 Decisions'!O6:O500,"Open")+COUNTIF('09 Decisions'!O6:O500,"Draft")+COUNTIF('09 Decisions'!O6:O500,"In Progress") -> 1 | D7: =IF('02 Source Inventory'!B7<>"",'02 Source Inventory'!B7,"") -> Grant Payments File | E7: =IF(D7<>"",'02 Source Inventory'!C7,"") -> Department of Finance | F7: =IF(D7<>"",'02 Source Inventory'!S7,"") -> Medium | G7: =IF(D7<>"",'02 Source Inventory'!T7,"") -> Medium | H7: =IF(D7<>"",'02 Source Inventory'!U7,"") -> Yes | I7: =IF(D7<>"",IFERROR(_xludf.XLOOKUP(D7,'03 Bronze Intake'!B$6:B$367,'03 Bronze Intake'!V$6:V$367,""),""),"") | J7: =IF(D7<>"",'02 Source Inventory'!D7,"") -> Chief Financial Officer
A8: Open RAID items | B8: =COUNTIF('10 RAID Log'!J6:J500,"Open")+COUNTIF('10 RAID Log'!J6:J500,"In Progress")+COUNTIF('10 RAID Log'!J6:J500,"Blocked") -> 2 | D8: =IF('02 Source Inventory'!B8<>"",'02 Source Inventory'!B8,"") | E8: =IF(D8<>"",'02 Source Inventory'!C8,"") | F8: =IF(D8<>"",'02 Source Inventory'!S8,"") | G8: =IF(D8<>"",'02 Source Inventory'!T8,"") | H8: =IF(D8<>"",'02 Source Inventory'!U8,"") | I8: =IF(D8<>"",IFERROR(_xludf.XLOOKUP(D8,'03 Bronze Intake'!B$6:B$367,'03 Bronze Intake'!V$6:V$367,""),""),"") | J8: =IF(D8<>"",'02 Source Inventory'!D8,"")
A9: Gold products defined | B9: =COUNTA('06 Gold Product'!B6:B500) -> 1 | D9: =IF('02 Source Inventory'!B9<>"",'02 Source Inventory'!B9,"") | E9: =IF(D9<>"",'02 Source Inventory'!C9,"") | F9: =IF(D9<>"",'02 Source Inventory'!S9,"") | G9: =IF(D9<>"",'02 Source Inventory'!T9,"") | H9: =IF(D9<>"",'02 Source Inventory'!U9,"") | I9: =IF(D9<>"",IFERROR(_xludf.XLOOKUP(D9,'03 Bronze Intake'!B$6:B$367,'03 Bronze Intake'!V$6:V$367,""),""),"") | J9: =IF(D9<>"",'02 Source Inventory'!D9,"")
D10: =IF('02 Source Inventory'!B10<>"",'02 Source Inventory'!B10,"") | E10: =IF(D10<>"",'02 Source Inventory'!C10,"") | F10: =IF(D10<>"",'02 Source Inventory'!S10,"") | G10: =IF(D10<>"",'02 Source Inventory'!T10,"") | H10: =IF(D10<>"",'02 Source Inventory'!U10,"") | I10: =IF(D10<>"",IFERROR(_xludf.XLOOKUP(D10,'03 Bronze Intake'!B$6:B$367,'03 Bronze Intake'!V$6:V$367,""),""),"") | J10: =IF(D10<>"",'02 Source Inventory'!D10,"")
D11: =IF('02 Source Inventory'!B11<>"",'02 Source Inventory'!B11,"") | E11: =IF(D11<>"",'02 Source Inventory'!C11,"") | F11: =IF(D11<>"",'02 Source Inventory'!S11,"") | G11: =IF(D11<>"",'02 Source Inventory'!T11,"") | H11: =IF(D11<>"",'02 Source Inventory'!U11,"") | I11: =IF(D11<>"",IFERROR(_xludf.XLOOKUP(D11,'03 Bronze Intake'!B$6:B$367,'03 Bronze Intake'!V$6:V$367,""),""),"") | J11: =IF(D11<>"",'02 Source Inventory'!D11,"")
A12: Open decisions | G12: =IF(D12<>"",'02 Source Inventory'!T12,"") | H12: Open RAID items
A13: Decision ID | B13: Topic | C13: Scope | D13: Decision Statement | E13: Action Owner | F13: Status | G13: =IF(D13<>"",'02 Source Inventory'!T13,"") -> 0 | H13: RAID ID | I13: Type | J13: Source / Domain | K13: Description | L13: Owner | M13: Status
A14: {=IF('09 Decisions'!A6<>"",'09 Decisions'!A6,"")} -> DEC-001 | B14: =IF(A14<>"",'09 Decisions'!C6,"") -> Vendor access design | C14: =IF(A14<>"",'09 Decisions'!D6,"") -> Enterprise Licensing System | D14: =IF(A14<>"",'09 Decisions'!E6,"") -> Silver will be designed for enterprise reuse first; vendor-specific shaping will occur through downstream curated extracts or Gold products. | E14: =IF(A14<>"",'09 Decisions'!M6,"") -> Data strategy lead | F14: =IF(A14<>"",'09 Decisions'!O6,"") -> Open | G14: =IF(D14<>"",'02 Source Inventory'!T14,"") -> 0 | H14: {=IF('10 RAID Log'!A6<>"",'10 RAID Log'!A6,"")} -> RAID-001 | I14: =IF(H14<>"",'10 RAID Log'!B6,"") -> Risk | J14: =IF(H14<>"",'10 RAID Log'!D6,"") -> Enterprise Licensing System | K14: =IF(H14<>"",'10 RAID Log'!E6,"") -> One source contains roughly 900 variables, which could overwhelm the first workshop if the team tries to define every field in one session. | L14: =IF(H14<>"",'10 RAID Log'!I6,"") -> Facilitator | M14: =IF(H14<>"",'10 RAID Log'!J6,"") -> Open
A15: =IF('09 Decisions'!A7<>"",'09 Decisions'!A7,"") | B15: =IF(A15<>"",'09 Decisions'!C7,"") | C15: =IF(A15<>"",'09 Decisions'!D7,"") | D15: =IF(A15<>"",'09 Decisions'!E7,"") | E15: =IF(A15<>"",'09 Decisions'!M7,"") | F15: =IF(A15<>"",'09 Decisions'!O7,"") | G15: =IF(D15<>"",'02 Source Inventory'!T15,"") | H15: RAID-001 | I15: =IF(H15<>"",'10 RAID Log'!B7,"") -> Dependency | J15: =IF(H15<>"",'10 RAID Log'!D7,"") -> Grant Payments File | K15: =IF(H15<>"",'10 RAID Log'!E7,"") -> Chart-of-accounts reference list is not yet confirmed. | L15: =IF(H15<>"",'10 RAID Log'!I7,"") -> Finance steward | M15: =IF(H15<>"",'10 RAID Log'!J7,"") -> Open
A16: =IF('09 Decisions'!A8<>"",'09 Decisions'!A8,"") | B16: =IF(A16<>"",'09 Decisions'!C8,"") | C16: =IF(A16<>"",'09 Decisions'!D8,"") | D16: =IF(A16<>"",'09 Decisions'!E8,"") | E16: =IF(A16<>"",'09 Decisions'!M8,"") | F16: =IF(A16<>"",'09 Decisions'!O8,"") | G16: =IF(D16<>"",'02 Source Inventory'!T16,"") | H16: =IF('10 RAID Log'!A8<>"",'10 RAID Log'!A8,"") | I16: =IF(H16<>"",'10 RAID Log'!B8,"") | J16: =IF(H16<>"",'10 RAID Log'!D8,"") | K16: =IF(H16<>"",'10 RAID Log'!E8,"") | L16: =IF(H16<>"",'10 RAID Log'!I8,"") | M16: =IF(H16<>"",'10 RAID Log'!J8,"")
A17: =IF('09 Decisions'!A9<>"",'09 Decisions'!A9,"") | B17: =IF(A17<>"",'09 Decisions'!C9,"") | C17: =IF(A17<>"",'09 Decisions'!D9,"") | D17: =IF(A17<>"",'09 Decisions'!E9,"") | E17: =IF(A17<>"",'09 Decisions'!M9,"") | F17: =IF(A17<>"",'09 Decisions'!O9,"") | G17: =IF(D17<>"",'02 Source Inventory'!T17,"") | H17: =IF('10 RAID Log'!A9<>"",'10 RAID Log'!A9,"") | I17: =IF(H17<>"",'10 RAID Log'!B9,"") | J17: =IF(H17<>"",'10 RAID Log'!D9,"") | K17: =IF(H17<>"",'10 RAID Log'!E9,"") | L17: =IF(H17<>"",'10 RAID Log'!I9,"") | M17: =IF(H17<>"",'10 RAID Log'!J9,"")
A18: =IF('09 Decisions'!A10<>"",'09 Decisions'!A10,"") | B18: =IF(A18<>"",'09 Decisions'!C10,"") | C18: =IF(A18<>"",'09 Decisions'!D10,"") | D18: =IF(A18<>"",'09 Decisions'!E10,"") | E18: =IF(A18<>"",'09 Decisions'!M10,"") | F18: =IF(A18<>"",'09 Decisions'!O10,"") | G18: =IF(D18<>"",'02 Source Inventory'!T18,"") | H18: =IF('10 RAID Log'!A10<>"",'10 RAID Log'!A10,"") | I18: =IF(H18<>"",'10 RAID Log'!B10,"") | J18: =IF(H18<>"",'10 RAID Log'!D10,"") | K18: =IF(H18<>"",'10 RAID Log'!E10,"") | L18: =IF(H18<>"",'10 RAID Log'!I10,"") | M18: =IF(H18<>"",'10 RAID Log'!J10,"")
A19: =IF('09 Decisions'!A11<>"",'09 Decisions'!A11,"") | B19: =IF(A19<>"",'09 Decisions'!C11,"") | C19: =IF(A19<>"",'09 Decisions'!D11,"") | D19: =IF(A19<>"",'09 Decisions'!E11,"") | E19: =IF(A19<>"",'09 Decisions'!M11,"") | F19: =IF(A19<>"",'09 Decisions'!O11,"") | G19: =IF(D19<>"",'02 Source Inventory'!T19,"") | H19: =IF('10 RAID Log'!A11<>"",'10 RAID Log'!A11,"") | I19: =IF(H19<>"",'10 RAID Log'!B11,"") | J19: =IF(H19<>"",'10 RAID Log'!D11,"") | K19: =IF(H19<>"",'10 RAID Log'!E11,"") | L19: =IF(H19<>"",'10 RAID Log'!I11,"") | M19: =IF(H19<>"",'10 RAID Log'!J11,"")
A20: =IF('09 Decisions'!A12<>"",'09 Decisions'!A12,"") | B20: =IF(A20<>"",'09 Decisions'!C12,"") | C20: =IF(A20<>"",'09 Decisions'!D12,"") | D20: =IF(A20<>"",'09 Decisions'!E12,"") | E20: =IF(A20<>"",'09 Decisions'!M12,"") | F20: =IF(A20<>"",'09 Decisions'!O12,"") | G20: =IF(D20<>"",'02 Source Inventory'!T20,"") | H20: =IF('10 RAID Log'!A12<>"",'10 RAID Log'!A12,"") | I20: =IF(H20<>"",'10 RAID Log'!B12,"") | J20: =IF(H20<>"",'10 RAID Log'!D12,"") | K20: =IF(H20<>"",'10 RAID Log'!E12,"") | L20: =IF(H20<>"",'10 RAID Log'!I12,"") | M20: =IF(H20<>"",'10 RAID Log'!J12,"")
A21: =IF('09 Decisions'!A13<>"",'09 Decisions'!A13,"") | B21: =IF(A21<>"",'09 Decisions'!C13,"") | C21: =IF(A21<>"",'09 Decisions'!D13,"") | D21: =IF(A21<>"",'09 Decisions'!E13,"") | E21: =IF(A21<>"",'09 Decisions'!M13,"") | F21: =IF(A21<>"",'09 Decisions'!O13,"") | G21: =IF(D21<>"",'02 Source Inventory'!T21,"") | H21: =IF('10 RAID Log'!A13<>"",'10 RAID Log'!A13,"") | I21: =IF(H21<>"",'10 RAID Log'!B13,"") | J21: =IF(H21<>"",'10 RAID Log'!D13,"") | K21: =IF(H21<>"",'10 RAID Log'!E13,"") | L21: =IF(H21<>"",'10 RAID Log'!I13,"") | M21: =IF(H21<>"",'10 RAID Log'!J13,"")
A22: =IF('09 Decisions'!A14<>"",'09 Decisions'!A14,"") | B22: =IF(A22<>"",'09 Decisions'!C14,"") | C22: =IF(A22<>"",'09 Decisions'!D14,"") | D22: =IF(A22<>"",'09 Decisions'!E14,"") | E22: =IF(A22<>"",'09 Decisions'!M14,"") | F22: =IF(A22<>"",'09 Decisions'!O14,"") | G22: =IF(D22<>"",'02 Source Inventory'!T22,"") | H22: =IF('10 RAID Log'!A14<>"",'10 RAID Log'!A14,"") | I22: =IF(H22<>"",'10 RAID Log'!B14,"") | J22: =IF(H22<>"",'10 RAID Log'!D14,"") | K22: =IF(H22<>"",'10 RAID Log'!E14,"") | L22: =IF(H22<>"",'10 RAID Log'!I14,"") | M22: =IF(H22<>"",'10 RAID Log'!J14,"")
A23: =IF('09 Decisions'!A15<>"",'09 Decisions'!A15,"") | B23: =IF(A23<>"",'09 Decisions'!C15,"") | C23: =IF(A23<>"",'09 Decisions'!D15,"") | D23: =IF(A23<>"",'09 Decisions'!E15,"") | E23: =IF(A23<>"",'09 Decisions'!M15,"") | F23: =IF(A23<>"",'09 Decisions'!O15,"") | G23: =IF(D23<>"",'02 Source Inventory'!T23,"") | H23: =IF('10 RAID Log'!A15<>"",'10 RAID Log'!A15,"") | I23: =IF(H23<>"",'10 RAID Log'!B15,"") | J23: =IF(H23<>"",'10 RAID Log'!D15,"") | K23: =IF(H23<>"",'10 RAID Log'!E15,"") | L23: =IF(H23<>"",'10 RAID Log'!I15,"") | M23: =IF(H23<>"",'10 RAID Log'!J15,"")
A24: =IF('09 Decisions'!A16<>"",'09 Decisions'!A16,"") | B24: =IF(A24<>"",'09 Decisions'!C16,"") | C24: =IF(A24<>"",'09 Decisions'!D16,"") | D24: =IF(A24<>"",'09 Decisions'!E16,"") | E24: =IF(A24<>"",'09 Decisions'!M16,"") | F24: =IF(A24<>"",'09 Decisions'!O16,"") | G24: =IF(D24<>"",'02 Source Inventory'!T24,"") | H24: =IF('10 RAID Log'!A16<>"",'10 RAID Log'!A16,"") | I24: =IF(H24<>"",'10 RAID Log'!B16,"") | J24: =IF(H24<>"",'10 RAID Log'!D16,"") | K24: =IF(H24<>"",'10 RAID Log'!E16,"") | L24: =IF(H24<>"",'10 RAID Log'!I16,"") | M24: =IF(H24<>"",'10 RAID Log'!J16,"")
A25: =IF('09 Decisions'!A17<>"",'09 Decisions'!A17,"") | B25: =IF(A25<>"",'09 Decisions'!C17,"") | C25: =IF(A25<>"",'09 Decisions'!D17,"") | D25: =IF(A25<>"",'09 Decisions'!E17,"") | E25: =IF(A25<>"",'09 Decisions'!M17,"") | F25: =IF(A25<>"",'09 Decisions'!O17,"") | G25: =IF(D25<>"",'02 Source Inventory'!T25,"") | H25: =IF('10 RAID Log'!A17<>"",'10 RAID Log'!A17,"") | I25: =IF(H25<>"",'10 RAID Log'!B17,"") | J25: =IF(H25<>"",'10 RAID Log'!D17,"") | K25: =IF(H25<>"",'10 RAID Log'!E17,"") | L25: =IF(H25<>"",'10 RAID Log'!I17,"") | M25: =IF(H25<>"",'10 RAID Log'!J17,"")
A26: =IF('09 Decisions'!A18<>"",'09 Decisions'!A18,"") | B26: =IF(A26<>"",'09 Decisions'!C18,"") | C26: =IF(A26<>"",'09 Decisions'!D18,"") | D26: =IF(A26<>"",'09 Decisions'!E18,"") | E26: =IF(A26<>"",'09 Decisions'!M18,"") | F26: =IF(A26<>"",'09 Decisions'!O18,"") | G26: =IF(D26<>"",'02 Source Inventory'!T26,"") | H26: =IF('10 RAID Log'!A18<>"",'10 RAID Log'!A18,"") | I26: =IF(H26<>"",'10 RAID Log'!B18,"") | J26: =IF(H26<>"",'10 RAID Log'!D18,"") | K26: =IF(H26<>"",'10 RAID Log'!E18,"") | L26: =IF(H26<>"",'10 RAID Log'!I18,"") | M26: =IF(H26<>"",'10 RAID Log'!J18,"")
A27: =IF('09 Decisions'!A19<>"",'09 Decisions'!A19,"") | B27: =IF(A27<>"",'09 Decisions'!C19,"") | C27: =IF(A27<>"",'09 Decisions'!D19,"") | D27: =IF(A27<>"",'09 Decisions'!E19,"") | E27: =IF(A27<>"",'09 Decisions'!M19,"") | F27: =IF(A27<>"",'09 Decisions'!O19,"") | G27: =IF(D27<>"",'02 Source Inventory'!T27,"") | H27: =IF('10 RAID Log'!A19<>"",'10 RAID Log'!A19,"") | I27: =IF(H27<>"",'10 RAID Log'!B19,"") | J27: =IF(H27<>"",'10 RAID Log'!D19,"") | K27: =IF(H27<>"",'10 RAID Log'!E19,"") | L27: =IF(H27<>"",'10 RAID Log'!I19,"") | M27: =IF(H27<>"",'10 RAID Log'!J19,"")
... A33: =IF('09 Decisions'!A25<>"",'09 Decisions'!A25,"") | B33: =IF(A33<>"",'09 Decisions'!C25,"") | C33: =IF(A33<>"",'09 Decisions'!D25,"") | D33: =IF(A33<>"",'09 Decisions'!E25,"") | E33: =IF(A33<>"",'09 Decisions'!M25,"") | F33: =IF(A33<>"",'09 Decisions'!O25,"") | G33: =IF(D33<>"",'02 Source Inventory'!T33,"") | H33: =IF('10 RAID Log'!A25<>"",'10 RAID Log'!A25,"") | I33: =IF(H33<>"",'10 RAID Log'!B25,"") | J33: =IF(H33<>"",'10 RAID Log'!D25,"") | K33: =IF(H33<>"",'10 RAID Log'!E25,"") | L33: =IF(H33<>"",'10 RAID Log'!I25,"") | M33: =IF(H33<>"",'10 RAID Log'!J25,"")
D34: =IF('02 Source Inventory'!B34<>"",'02 Source Inventory'!B34,"") | E34: =IF(D34<>"",'02 Source Inventory'!C34,"") | F34: =IF(D34<>"",'02 Source Inventory'!S34,"") | G34: =IF(D34<>"",'02 Source Inventory'!T34,"") | H34: =IF(D34<>"",'02 Source Inventory'!U34,"") | I34: =IF(D34<>"",IFERROR(_xludf.XLOOKUP(D34,'03 Bronze Intake'!B$6:B$367,'03 Bronze Intake'!V$6:V$367,""),""),"") | J34: =IF(D34<>"",'02 Source Inventory'!D34,"")
D35: =IF('02 Source Inventory'!B35<>"",'02 Source Inventory'!B35,"") | E35: =IF(D35<>"",'02 Source Inventory'!C35,"") | F35: =IF(D35<>"",'02 Source Inventory'!S35,"") | G35: =IF(D35<>"",'02 Source Inventory'!T35,"") | H35: =IF(D35<>"",'02 Source Inventory'!U35,"") | I35: =IF(D35<>"",IFERROR(_xludf.XLOOKUP(D35,'03 Bronze Intake'!B$6:B$367,'03 Bronze Intake'!V$6:V$367,""),""),"") | J35: =IF(D35<>"",'02 Source Inventory'!D35,"")
D36: =IF('02 Source Inventory'!B36<>"",'02 Source Inventory'!B36,"") | E36: =IF(D36<>"",'02 Source Inventory'!C36,"") | F36: =IF(D36<>"",'02 Source Inventory'!S36,"") | G36: =IF(D36<>"",'02 Source Inventory'!T36,"") | H36: =IF(D36<>"",'02 Source Inventory'!U36,"") | I36: =IF(D36<>"",IFERROR(_xludf.XLOOKUP(D36,'03 Bronze Intake'!B$6:B$367,'03 Bronze Intake'!V$6:V$367,""),""),"") | J36: =IF(D36<>"",'02 Source Inventory'!D36,"")
D37: =IF('02 Source Inventory'!B37<>"",'02 Source Inventory'!B37,"") | E37: =IF(D37<>"",'02 Source Inventory'!C37,"") | F37: =IF(D37<>"",'02 Source Inventory'!S37,"") | G37: =IF(D37<>"",'02 Source Inventory'!T37,"") | H37: =IF(D37<>"",'02 Source Inventory'!U37,"") | I37: =IF(D37<>"",IFERROR(_xludf.XLOOKUP(D37,'03 Bronze Intake'!B$6:B$367,'03 Bronze Intake'!V$6:V$367,""),""),"") | J37: =IF(D37<>"",'02 Source Inventory'!D37,"")
D38: =IF('02 Source Inventory'!B38<>"",'02 Source Inventory'!B38,"") | E38: =IF(D38<>"",'02 Source Inventory'!C38,"") | F38: =IF(D38<>"",'02 Source Inventory'!S38,"") | G38: =IF(D38<>"",'02 Source Inventory'!T38,"") | H38: =IF(D38<>"",'02 Source Inventory'!U38,"") | I38: =IF(D38<>"",IFERROR(_xludf.XLOOKUP(D38,'03 Bronze Intake'!B$6:B$367,'03 Bronze Intake'!V$6:V$367,""),""),"") | J38: =IF(D38<>"",'02 Source Inventory'!D38,"")
D39: =IF('02 Source Inventory'!B39<>"",'02 Source Inventory'!B39,"") | E39: =IF(D39<>"",'02 Source Inventory'!C39,"") | F39: =IF(D39<>"",'02 Source Inventory'!S39,"") | G39: =IF(D39<>"",'02 Source Inventory'!T39,"") | H39: =IF(D39<>"",'02 Source Inventory'!U39,"") | I39: =IF(D39<>"",IFERROR(_xludf.XLOOKUP(D39,'03 Bronze Intake'!B$6:B$367,'03 Bronze Intake'!V$6:V$367,""),""),"") | J39: =IF(D39<>"",'02 Source Inventory'!D39,"")
D40: =IF('02 Source Inventory'!B40<>"",'02 Source Inventory'!B40,"") | E40: =IF(D40<>"",'02 Source Inventory'!C40,"") | F40: =IF(D40<>"",'02 Source Inventory'!S40,"") | G40: =IF(D40<>"",'02 Source Inventory'!T40,"") | H40: =IF(D40<>"",'02 Source Inventory'!U40,"") | I40: =IF(D40<>"",IFERROR(_xludf.XLOOKUP(D40,'03 Bronze Intake'!B$6:B$367,'03 Bronze Intake'!V$6:V$367,""),""),"") | J40: =IF(D40<>"",'02 Source Inventory'!D40,"")
D41: =IF('02 Source Inventory'!B41<>"",'02 Source Inventory'!B41,"") | E41: =IF(D41<>"",'02 Source Inventory'!C41,"") | F41: =IF(D41<>"",'02 Source Inventory'!S41,"") | G41: =IF(D41<>"",'02 Source Inventory'!T41,"") | H41: =IF(D41<>"",'02 Source Inventory'!U41,"") | I41: =IF(D41<>"",IFERROR(_xludf.XLOOKUP(D41,'03 Bronze Intake'!B$6:B$367,'03 Bronze Intake'!V$6:V$367,""),""),"") | J41: =IF(D41<>"",'02 Source Inventory'!D41,"")
D42: =IF('02 Source Inventory'!B42<>"",'02 Source Inventory'!B42,"") | E42: =IF(D42<>"",'02 Source Inventory'!C42,"") | F42: =IF(D42<>"",'02 Source Inventory'!S42,"") | G42: =IF(D42<>"",'02 Source Inventory'!T42,"") | H42: =IF(D42<>"",'02 Source Inventory'!U42,"") | I42: =IF(D42<>"",IFERROR(_xludf.XLOOKUP(D42,'03 Bronze Intake'!B$6:B$367,'03 Bronze Intake'!V$6:V$367,""),""),"") | J42: =IF(D42<>"",'02 Source Inventory'!D42,"")
D43: =IF('02 Source Inventory'!B43<>"",'02 Source Inventory'!B43,"") | E43: =IF(D43<>"",'02 Source Inventory'!C43,"") | F43: =IF(D43<>"",'02 Source Inventory'!S43,"") | G43: =IF(D43<>"",'02 Source Inventory'!T43,"") | H43: =IF(D43<>"",'02 Source Inventory'!U43,"") | I43: =IF(D43<>"",IFERROR(_xludf.XLOOKUP(D43,'03 Bronze Intake'!B$6:B$367,'03 Bronze Intake'!V$6:V$367,""),""),"") | J43: =IF(D43<>"",'02 Source Inventory'!D43,"")
D44: =IF('02 Source Inventory'!B44<>"",'02 Source Inventory'!B44,"") | E44: =IF(D44<>"",'02 Source Inventory'!C44,"") | F44: =IF(D44<>"",'02 Source Inventory'!S44,"") | G44: =IF(D44<>"",'02 Source Inventory'!T44,"") | H44: =IF(D44<>"",'02 Source Inventory'!U44,"") | I44: =IF(D44<>"",IFERROR(_xludf.XLOOKUP(D44,'03 Bronze Intake'!B$6:B$367,'03 Bronze Intake'!V$6:V$367,""),""),"") | J44: =IF(D44<>"",'02 Source Inventory'!D44,"")
D45: =IF('02 Source Inventory'!B45<>"",'02 Source Inventory'!B45,"") | E45: =IF(D45<>"",'02 Source Inventory'!C45,"") | F45: =IF(D45<>"",'02 Source Inventory'!S45,"") | G45: =IF(D45<>"",'02 Source Inventory'!T45,"") | H45: =IF(D45<>"",'02 Source Inventory'!U45,"") | I45: =IF(D45<>"",IFERROR(_xludf.XLOOKUP(D45,'03 Bronze Intake'!B$6:B$367,'03 Bronze Intake'!V$6:V$367,""),""),"") | J45: =IF(D45<>"",'02 Source Inventory'!D45,"")
... D105: =IF('02 Source Inventory'!B105<>"",'02 Source Inventory'!B105,"") | E105: =IF(D105<>"",'02 Source Inventory'!C105,"") | F105: =IF(D105<>"",'02 Source Inventory'!S105,"") | G105: =IF(D105<>"",'02 Source Inventory'!T105,"") | H105: =IF(D105<>"",'02 Source Inventory'!U105,"") | I105: =IF(D105<>"",IFERROR(_xludf.XLOOKUP(D105,'03 Bronze Intake'!B$6:B$367,'03 Bronze Intake'!V$6:V$367,""),""),"") | J105: =IF(D105<>"",'02 Source Inventory'!D105,"")

Sheet 91 Data Steward View
A1: 91 Data Steward View
A2: Generated role-based view — do not edit. Generated view — do not edit. This steward-focused view pulls the business-facing Silver treatment, quality, and governance columns from the core source tabs. Update the source tabs and refresh the workbook instead of editing this view directly.
A4: Source Name | B4: Source Table / File | C4: Record Grain | D4: Business Entity | E4: Source Field Name | F4: Source Definition | G4: Target Silver Field | H4: Target Silver Definition | I4: Keep in Silver? | J4: Treatment Category | K4: Transformation Rule Summary | L4: Decision Status | M4: Owner / Reviewer | N4: Open Issue / Note | O4: Sensitive Classification | P4: Data Quality Rules | Q4: Source of Truth / Authority Note
A5: {=IF('04B Silver Field Treatment'!A6<>"",'04B Silver Field Treatment'!A6,"")} -> Enterprise Licensing System | B5: =IF(A5<>"",'04B Silver Field Treatment'!B6,"") -> brz_licensing_license_master | C5: =IF(A5<>"",'04B Silver Field Treatment'!C6,"") -> Licensing License Silver | D5: =IF(A5<>"",'04B Silver Field Treatment'!#REF!,"") -> #REF! | E5: =IF(A5<>"",'04B Silver Field Treatment'!D6,"") -> license_status | F5: =IF(A5<>"",'04B Silver Field Treatment'!F6,"") -> Current status recorded by licensing program | G5: =IF(A5<>"",'04B Silver Field Treatment'!K6,"") -> license_status_code | H5: =IF(A5<>"",'04B Silver Field Treatment'!L6,"") -> Normalized current license status | I5: =IF(A5<>"",'04B Silver Field Treatment'!M6,"") -> Yes | J5: =IF(A5<>"",'04B Silver Field Treatment'!N6,"") -> Map | K5: =IF(A5<>"",'04B Silver Field Treatment'!O6,"") -> Map source statuses to enterprise licensing status list | L5: =IF(A5<>"",'04B Silver Field Treatment'!P6,"") -> In Progress | M5: =IF(A5<>"",'04B Silver Field Treatment'!Q6,"") -> Licensing steward | N5: =IF(A5<>"",'04B Silver Field Treatment'!R6,"") -> Need decision on how to handle pending-renewal versus active. | O5: =IF(A5<>"",'04B Silver Field Treatment'!S6,"") -> Internal | P5: =IF(A5<>"",'04B Silver Field Treatment'!V6,"") -> DQ-004 | Q5: =IF(A5<>"",'04B Silver Field Treatment'!W6,"") -> Licensing source authoritative unless superseded by adjudication feed
A6: Enterprise Licensing System | B6: =IF(A6<>"",'04B Silver Field Treatment'!B7,"") -> brz_finance_payments_weekly | C6: =IF(A6<>"",'04B Silver Field Treatment'!C7,"") -> Grant Payment Silver | D6: =IF(A6<>"",'04B Silver Field Treatment'!#REF!,"") -> #REF! | E6: =IF(A6<>"",'04B Silver Field Treatment'!D7,"") -> amount | F6: =IF(A6<>"",'04B Silver Field Treatment'!F7,"") -> Dollar amount of payment transaction | G6: =IF(A6<>"",'04B Silver Field Treatment'!K7,"") -> payment_amount | H6: =IF(A6<>"",'04B Silver Field Treatment'!L7,"") -> Payment amount in USD | I6: =IF(A6<>"",'04B Silver Field Treatment'!M7,"") -> Yes | J6: =IF(A6<>"",'04B Silver Field Treatment'!N7,"") -> Validate | K6: =IF(A6<>"",'04B Silver Field Treatment'!O7,"") -> Preserve numeric value and validate non-negative unless reversal indicator present | L6: =IF(A6<>"",'04B Silver Field Treatment'!P7,"") -> Draft | M6: =IF(A6<>"",'04B Silver Field Treatment'!Q7,"") -> Finance steward | N6: =IF(A6<>"",'04B Silver Field Treatment'!R7,"") -> Need rule for zero-dollar adjustment rows. | O6: =IF(A6<>"",'04B Silver Field Treatment'!S7,"") -> Confidential | P6: =IF(A6<>"",'04B Silver Field Treatment'!V7,"") -> DQ-007 | Q6: =IF(A6<>"",'04B Silver Field Treatment'!W7,"") -> Finance file authoritative for disbursement amount
A7: =IF('04B Silver Field Treatment'!A8<>"",'04B Silver Field Treatment'!A8,"") | B7: =IF(A7<>"",'04B Silver Field Treatment'!B8,"") | C7: =IF(A7<>"",'04B Silver Field Treatment'!C8,"") | D7: =IF(A7<>"",'04B Silver Field Treatment'!#REF!,"") | E7: =IF(A7<>"",'04B Silver Field Treatment'!D8,"") | F7: =IF(A7<>"",'04B Silver Field Treatment'!F8,"") | G7: =IF(A7<>"",'04B Silver Field Treatment'!K8,"") | H7: =IF(A7<>"",'04B Silver Field Treatment'!L8,"") | I7: =IF(A7<>"",'04B Silver Field Treatment'!M8,"") | J7: =IF(A7<>"",'04B Silver Field Treatment'!N8,"") | K7: =IF(A7<>"",'04B Silver Field Treatment'!O8,"") | L7: =IF(A7<>"",'04B Silver Field Treatment'!P8,"") | M7: =IF(A7<>"",'04B Silver Field Treatment'!Q8,"") | N7: =IF(A7<>"",'04B Silver Field Treatment'!R8,"") | O7: =IF(A7<>"",'04B Silver Field Treatment'!S8,"") | P7: =IF(A7<>"",'04B Silver Field Treatment'!V8,"") | Q7: =IF(A7<>"",'04B Silver Field Treatment'!W8,"")
A8: =IF('04B Silver Field Treatment'!A9<>"",'04B Silver Field Treatment'!A9,"") | B8: =IF(A8<>"",'04B Silver Field Treatment'!B9,"") | C8: =IF(A8<>"",'04B Silver Field Treatment'!C9,"") | D8: =IF(A8<>"",'04B Silver Field Treatment'!#REF!,"") | E8: =IF(A8<>"",'04B Silver Field Treatment'!D9,"") | F8: =IF(A8<>"",'04B Silver Field Treatment'!F9,"") | G8: =IF(A8<>"",'04B Silver Field Treatment'!K9,"") | H8: =IF(A8<>"",'04B Silver Field Treatment'!L9,"") | I8: =IF(A8<>"",'04B Silver Field Treatment'!M9,"") | J8: =IF(A8<>"",'04B Silver Field Treatment'!N9,"") | K8: =IF(A8<>"",'04B Silver Field Treatment'!O9,"") | L8: =IF(A8<>"",'04B Silver Field Treatment'!P9,"") | M8: =IF(A8<>"",'04B Silver Field Treatment'!Q9,"") | N8: =IF(A8<>"",'04B Silver Field Treatment'!R9,"") | O8: =IF(A8<>"",'04B Silver Field Treatment'!S9,"") | P8: =IF(A8<>"",'04B Silver Field Treatment'!V9,"") | Q8: =IF(A8<>"",'04B Silver Field Treatment'!W9,"")
